<?xml version="1.0"?>
<robot name="my_robot" xmlns:xacro="http://www.ros.org/wiki/xacro">

  <!-- Materials -->
  <material name="black">
    <color rgba="0 0 0 1"/>
  </material>
  <material name="blue">
    <color rgba="0 0 1 1"/>
  </material>

  <!-- Base link -->
  <link name="base_link">
    <visual>
      <geometry>
        <cylinder radius="0.2" length="0.1"/>
      </geometry>
      <material name="black"/>
    </visual>
    <collision>
      <geometry>
        <cylinder radius="0.2" length="0.1"/>
      </geometry>
    </collision>
    <inertial>
      <mass value="1.0"/>
      <inertia ixx="0.1" iyy="0.1" izz="0.1" ixy="0.0" ixz="0.0" iyz="0.0"/>
    </inertial>
  </link>

  <!-- Link 1 -->
  <link name="link1">
    <visual>
      <geometry>
        <box size="0.1 0.1 0.5"/>
      </geometry>
      <origin xyz="0 0 0.25"/>
      <material name="blue"/>
    </visual>
    <collision>
      <geometry>
        <box size="0.1 0.1 0.5"/>
      </geometry>
      <origin xyz="0 0 0.25"/>
    </collision>
    <inertial>
      <mass value="0.5"/>
      <inertia ixx="0.02" iyy="0.02" izz="0.02" ixy="0" ixz="0" iyz="0"/>
    </inertial>
  </link>

  <!-- Joint1: revolute around Z -->
  <joint name="joint1" type="revolute">
    <parent link="base_link"/>
    <child link="link1"/>
    <origin xyz="0 0 0.05" rpy="0 0 0"/>
    <axis xyz="0 0 1"/>
    <limit lower="-3.14" upper="3.14" effort="5.0" velocity="1.0"/>
  </joint>

  <!-- Link 2 -->
  <link name="link2">
    <visual>
      <geometry>
        <box size="0.1 0.1 0.5"/>
      </geometry>
      <origin xyz="0 0 0.25"/>
      <material name="black"/>
    </visual>
    <collision>
      <geometry>
        <box size="0.1 0.1 0.5"/>
      </geometry>
      <origin xyz="0 0 0.25"/>
    </collision>
    <inertial>
      <mass value="0.5"/>
      <inertia ixx="0.02" iyy="0.02" izz="0.02" ixy="0" ixz="0" iyz="0"/>
    </inertial>
  </link>

  <!-- Joint2: revolute around Y -->
  <joint name="joint2" type="revolute">
    <parent link="link1"/>
    <child link="link2"/>
    <origin xyz="0 0 0.5" rpy="0 0 0"/>
    <axis xyz="0 1 0"/>
    <limit lower="-1.57" upper="1.57" effort="5.0" velocity="1.0"/>
  </joint>

  <!-- Link 3 -->
  <link name="link3">
    <visual>
      <geometry>
        <box size="0.1 0.1 0.5"/>
      </geometry>
      <origin xyz="0 0 0.25"/>
      <material name="blue"/>
    </visual>
    <collision>
      <geometry>
        <box size="0.1 0.1 0.5"/>
      </geometry>
      <origin xyz="0 0 0.25"/>
    </collision>
    <inertial>
      <mass value="0.5"/>
      <inertia ixx="0.02" iyy="0.02" izz="0.02" ixy="0" ixz="0" iyz="0"/>
    </inertial>
  </link>

  <!-- Joint3: revolute around Y -->
  <joint name="joint3" type="revolute">
    <parent link="link2"/>
    <child link="link3"/>
    <origin xyz="0 0 0.5" rpy="0 0 0"/>
    <axis xyz="0 1 0"/>
    <limit lower="-1.57" upper="1.57" effort="5.0" velocity="1.0"/>
  </joint>

</robot>
